external fun foo() {
    let x = 1
    // TODO: why does this produce duplicate errors?
    x + 1 = 2
}

// args: check
// expected exit status: 1
// expected stdout:
// Error: Expected an expression, got: `=`.
// --> src/test_files/check/assign_not_lvalue.gdn:4
//     x + 1 = 2
//           ^
// 
// Error: Expected `}`, got `=`
// --> src/test_files/check/assign_not_lvalue.gdn:4
//     x + 1 = 2
//           ^
// 
// Error: Expected an expression, got: `=`.
// --> src/test_files/check/assign_not_lvalue.gdn:4
//     x + 1 = 2
//           ^

